Workbook

Sheet Leia-me
A1: Protocolo 3.0 · Benchmark de precos praticados por concorrentes no setor publico
A3: Fonte dos dados
A5: Portal Nacional de Contratacoes Publicas (PNCP) - API publica de consulta de contratos. Coleta em 03/09/2026.
A6: 1Doc Tecnologia S.A. - CNPJ 19.625.833/0001-76 · 196 contratos localizados, 114 aderentes ao objeto.
A7: Aprova Digital S/A - CNPJ 24.757.040/0001-40 · 57 localizados, 14 aderentes.
A8: Muove Brasil S.A. (marca Gove) - CNPJ 21.870.040/0001-64 · 34 localizados, 31 com valor e vigencia validos.
A9: Populacao municipal: IBGE, Estimativas da Populacao 2024 (agregado 6579, variavel 9324), cruzada pelo codigo IBGE do orgao.
A10: Grau de comparabilidade de cada concorrente
A12: 1Doc · BENCHMARK DIRETO. Objeto identico ao Protocolo 3.0: protocolo, tramitacao de processos administrativos e gestao documental.
A13: Aprova Digital · ADJACENTE. Atua predominantemente em licenciamento de obras e alvaras. Referencia de teto, nao de preco comparavel.
A14: Gove / Muove Brasil · ADJACENTE, NAO COMPARAVEL NO OBJETO. Plataforma de inteligencia de dados, gestao tributaria e relacionamento
A15: com o cidadao. Nenhum dos contratos analisados tem por objeto tramitacao de processos administrativos ou protocolo eletronico.
... A42: Contratos 1Doc · Contratos Aprova · Contratos Gove · Resumo por faixa · Proposta de preco

Sheet Contratos 1Doc
A1: Orgao contratante | B1: Tipo de entidade | C1: Municipio | D1: UF | E1: Populacao 2024 | F1: Faixa populacional | G1: Ano | H1: Modalidade | I1: Inicio vigencia | J1: Fim vigencia | K1: Situacao | L1: Meses | M1: Valor global (R$) | N1: Valor mensal (R$) | O1: R$/hab/ano | P1: Categoria do objeto | Q1: Objeto contratado | R1: Link PNCP
A2: MUNICIPIO DE BOTUVERA | B2: Prefeitura | C2: Botuverá | D2: SC | E2: 5623 | F2: 1 · Ate 20 mil | G2: 2024 | H2: Dispensa | I2: 45344 | J2: 45710 | K2: =IF(J2>=TODAY(),"Vigente","Encerrado") -> Encerrado | L2: =ROUND((J2-I2)/30.44,1) -> 12 | M2: 24841.8 | N2: =IF(L2=0,"",M2/L2) -> 2070.15 | O2: =IF(E2=0,"",N2*12/E2) -> 4.4178908 | P2: Protocolo / tramitacao de processos administrativos | Q2: Referente contratação da plataforma eletrônica 1Doc para manutenção das atividades administrativas desse município. | R2: https://pncp.gov.br/app/contratos/contratos/83102350000196/2024/165
A3: MUNICIPIO DE SAO JOSE DO CERRITO | B3: Prefeitura | C3: São José do Cerrito | D3: SC | E3: 8755 | F3: 1 · Ate 20 mil | G3: 2025 | H3: Pregão - Eletrônico | I3: 45884 | J3: 46249 | K3: =IF(J3>=TODAY(),"Vigente","Encerrado") -> Encerrado | L3: =ROUND((J3-I3)/30.44,1) -> 12 | M3: 28800 | N3: =IF(L3=0,"",M3/L3) -> 2400 | O3: =IF(E3=0,"",N3*12/E3) -> 3.2895488 | P3: Protocolo / tramitacao de processos administrativos | Q3: Contratação de Empresa para Prestação de Serviços de Locação de Sistema Integrado e Oficial de Comunicação Interna, Externa, Gestão Documental e Central de Atendimento. | R3: https://pncp.gov.br/app/contratos/contratos/82777327000139/2025/1584
A4: MUNICIPIO DE CATANDUVAS | B4: Prefeitura | C4: Catanduvas | D4: PR | E4: 10627 | F4: 1 · Ate 20 mil | G4: 2026 | H4: Dispensa | I4: 46094 | J4: 46278 | K4: =IF(J4>=TODAY(),"Vigente","Encerrado") -> Vigente | L4: =ROUND((J4-I4)/30.44,1) -> 6 | M4: 14400 | N4: =IF(L4=0,"",M4/L4) -> 2400 | O4: =IF(E4=0,"",N4*12/E4) -> 2.7100781 | P4: Protocolo / tramitacao de processos administrativos | Q4: MODULO PROCESSO DIGITAL GESTAO DOCUMENTAL MEMORANDO CIRCULAR OUVIDORIA DIGITAL PROTOCOLO ELETRONICO PEDIDO E SIC OFICIO DIGITAL PROCESSO ADMINISTRATIVO WORKFLOW AVANCADO DE PROCESSOS | R4: https://pncp.gov.br/app/contratos/contratos/76208842000103/2026/3
A5: MUNICIPIO DE NOVA AURORA | B5: Prefeitura | C5: Nova Aurora | D5: PR | E5: 14219 | F5: 1 · Ate 20 mil | G5: 2025 | H5: Dispensa | I5: 45715 | J5: 46080 | K5: =IF(J5>=TODAY(),"Vigente","Encerrado") -> Encerrado | L5: =ROUND((J5-I5)/30.44,1) -> 12 | M5: 28800 | N5: =IF(L5=0,"",M5/L5) -> 2400 | O5: =IF(E5=0,"",N5*12/E5) -> 2.0254589 | P5: Protocolo / tramitacao de processos administrativos | Q5: Contratação de empresa para prestação de serviço locação de sistema SaaS integrado de gestão documental, protocolo externo e possibilidade de assinatura eletrônica através de certificado digital ICP-Brasil, contendo os s | R5: https://pncp.gov.br/app/contratos/contratos/76208859000152/2025/3
A6: MUNICIPIO DE DOM PEDRO DE ALCANTARA | B6: Prefeitura | C6: Dom Pedro de Alcântara | D6: RS | E6: 2617 | F6: 1 · Ate 20 mil | G6: 2025 | H6: Dispensa | I6: 45980 | J6: 46344 | K6: =IF(J6>=TODAY(),"Vigente","Encerrado") -> Vigente | L6: =ROUND((J6-I6)/30.44,1) -> 12 | M6: 28800 | N6: =IF(L6=0,"",M6/L6) -> 2400 | O6: =IF(E6=0,"",N6*12/E6) -> 11.004968 | P6: Protocolo / tramitacao de processos administrativos | Q6: Contratação de empresa para prestação de serviços de fornecimento, manutenção, suporte técnico e atualização de sistema SaaS (Software as a Service) integrado de gestão documental e protocolo eletrônico, com recursos de | R6: https://pncp.gov.br/app/contratos/contratos/01640339000115/2025/63
A7: MUNICIPIO DE ARAMINA | B7: Prefeitura | C7: Aramina | D7: SP | E7: 5526 | F7: 1 · Ate 20 mil | G7: 2024 | H7: Dispensa | I7: 45349 | J7: 45715 | K7: =IF(J7>=TODAY(),"Vigente","Encerrado") -> Encerrado | L7: =ROUND((J7-I7)/30.44,1) -> 12 | M7: 28800 | N7: =IF(L7=0,"",M7/L7) -> 2400 | O7: =IF(E7=0,"",N7*12/E7) -> 5.2117264 | P7: Protocolo / tramitacao de processos administrativos | Q7: CONTRATAÇÃO DE EMPRESA PARA PRESTAÇÃO DE SERVIÇO DE LOCAÇÃO DE SISTEMA INFORMATIZADO INTEGRADO E OFICIAL DE COMUNICAÇÃO INTERNA, EXTERNA, GESTÃO DOCUMENTAL E CENTRAL DE ATENDIMENTO, QUE TEM COMO OBJETIVO PADRONIZAR A COM | R7: https://pncp.gov.br/app/contratos/contratos/45323474000102/2024/105
A8: MUNICIPIO DE GRANDES RIOS | B8: Prefeitura | C8: Grandes Rios | D8: PR | E8: 5586 | F8: 1 · Ate 20 mil | G8: 2025 | H8: Pregão - Eletrônico | I8: 45999 | J8: 46364 | K8: =IF(J8>=TODAY(),"Vigente","Encerrado") -> Vigente | L8: =ROUND((J8-I8)/30.44,1) -> 12 | M8: 29888 | N8: =IF(L8=0,"",M8/L8) -> 2490.6667 | O8: =IF(E8=0,"",N8*12/E8) -> 5.3505192 | P8: Protocolo / tramitacao de processos administrativos | Q8: Contratação de tecnologia da informação para cessão de uso de software para tramitação e gestão de documentos, processos eletrônicos, assinatura eletrônica e controle de prazos e fluxo processual, em atendimento às secre | R8: https://pncp.gov.br/app/contratos/contratos/75741348000139/2025/122
A9: MUNICIPIO DE AGUDOS DO SUL | B9: Prefeitura | C9: Agudos do Sul | D9: PR | E9: 10646 | F9: 1 · Ate 20 mil | G9: 2026 | H9: Dispensa | I9: 46168 | J9: 46533 | K9: =IF(J9>=TODAY(),"Vigente","Encerrado") -> Vigente | L9: =ROUND((J9-I9)/30.44,1) -> 12 | M9: 30333.24 | N9: =IF(L9=0,"",M9/L9) -> 2527.77 | O9: =IF(E9=0,"",N9*12/E9) -> 2.8492617 | P9: Protocolo / tramitacao de processos administrativos | Q9: CONTRATAÇÃO DE EMPRESA ESPECIALIZADA NA PRESTAÇÃO DE SERVIÇOS DE LOCAÇÃO DE SISTEMA INTEGRADO E OFICIAL DE COMUNICAÇÃO INTERNA E EXTERNA, GESTÃO DOCUMENTAL, CENTRAL DE ATENDIMENTO E GESTÃO AVANÇADA DE PROCESSOS (WORKFLOW | R9: https://pncp.gov.br/app/contratos/contratos/76105667000110/2026/48
A10: MUNICIPIO DE VALE DE SAO DOMINGOS | B10: Prefeitura | C10: Vale de São Domingos | D10: MT | E10: 2907 | F10: 1 · Ate 20 mil | G10: 2025 | H10: Concorrência - Eletrônica | I10: 45874 | J10: 46239 | K10: =IF(J10>=TODAY(),"Vigente","Encerrado") -> Encerrado | L10: =ROUND((J10-I10)/30.44,1) -> 12 | M10: 32400 | N10: =IF(L10=0,"",M10/L10) -> 2700 | O10: =IF(E10=0,"",N10*12/E10) -> 11.145511 | P10: Protocolo / tramitacao de processos administrativos | Q10: CONTRATAÇÃO DE EMPRESA PARA O FORNECIMENTO DE SOFTWARE PARA TRAMITAÇÃO E GESTÃO DE DOCUMENTOS | R10: https://pncp.gov.br/app/contratos/contratos/04215993000170/2025/30
A11: MUNICIPIO DE MORRO REUTER | B11: Prefeitura | C11: Morro Reuter | D11: RS | E11: 6163 | F11: 1 · Ate 20 mil | G11: 2025 | H11: Dispensa | I11: 45962 | J11: 46327 | K11: =IF(J11>=TODAY(),"Vigente","Encerrado") -> Vigente | L11: =ROUND((J11-I11)/30.44,1) -> 12 | M11: 36000 | N11: =IF(L11=0,"",M11/L11) -> 3000 | O11: =IF(E11=0,"",N11*12/E11) -> 5.841311 | P11: Protocolo / tramitacao de processos administrativos | Q11: Contratacao de Sistema SaaS integrado de gestao documental protocolo externo e possibilidade de assinatura eletronica atraves de Certificado Digital ICP Brasil. | R11: https://pncp.gov.br/app/contratos/contratos/94707627000120/2025/132
A12: MUNICIPIO DE ACARI | B12: Prefeitura | C12: Acari | D12: RN | E12: 10865 | F12: 1 · Ate 20 mil | G12: 2025 | H12: Pregão - Eletrônico | I12: 45894 | J12: 46258 | K12: =IF(J12>=TODAY(),"Vigente","Encerrado") -> Encerrado | L12: =ROUND((J12-I12)/30.44,1) -> 12 | M12: 36180 | N12: =IF(L12=0,"",M12/L12) -> 3015 | O12: =IF(E12=0,"",N12*12/E12) -> 3.3299586 | P12: Protocolo / tramitacao de processos administrativos | Q12: CONTRATAÇÃO DE EMPRESA PARA O LICENCIAMENTO DE USO DE SOFTWARE, DENOMINADA PLATAFORMA “1DOC”, NOS TERMOS DESSE CONTRATO, DE FORMA ONEROSA, INTRANSFERÍVEL E NÃO EXCLUSIVA, COM AS FUNCIONALIDADES PREVISTAS DE GESTÃO, FORMA | R12: https://pncp.gov.br/app/contratos/contratos/08097008000120/2025/95
A13: MUNICIPIO DE BOTUVERA | B13: Prefeitura | C13: Botuverá | D13: SC | E13: 5623 | F13: 1 · Ate 20 mil | G13: 2026 | H13: Dispensa | I13: 46140 | J13: 46504 | K13: =IF(J13>=TODAY(),"Vigente","Encerrado") -> Vigente | L13: =ROUND((J13-I13)/30.44,1) -> 12 | M13: 36480 | N13: =IF(L13=0,"",M13/L13) -> 3040 | O13: =IF(E13=0,"",N13*12/E13) -> 6.48764 | P13: Protocolo / tramitacao de processos administrativos | Q13: Contratação da empresa 1Doc Tecnologia S.A., inscrita no CNPJ nº 19.625.833/0001-76, para fornecimento de sistema informatizado em modelo SaaS (Software as a Service), destinado à gestão integrada de processos administra | R13: https://pncp.gov.br/app/contratos/contratos/83102350000196/2026/614
... A115: ESTADO DE SAO PAULO | B115: Estado/Outro | C115: São Paulo | D115: SP | E115: 11895578 | F115: 4 · Acima de 500 mil | G115: 2025 | H115: Pregão - Eletrônico | I115: 45723 | J115: 46088 | K115: =IF(J115>=TODAY(),"Vigente","Encerrado") -> Encerrado | L115: =ROUND((J115-I115)/30.44,1) -> 12 | M115: 69600 | N115: =IF(L115=0,"",M115/L115) -> 5800 | O115: =IF(E115=0,"",N115*12/E115) -> 0.0058509137 | P115: Protocolo / tramitacao de processos administrativos | Q115: AQUISIÇÃO DE LICENÇA DE SOFTWARE PARA TRAMITAÇÃO E GESTÃO DE DOCUMENTOS, CONFORME SOLICITAÇÃO DO ADJUNTO ADMINISTRATIVO. | R115: https://pncp.gov.br/app/contratos/contratos/46379400000150/2025/398

Sheet Contratos Aprova
A1: Orgao contratante | B1: Tipo de entidade | C1: Municipio | D1: UF | E1: Populacao 2024 | F1: Faixa populacional | G1: Ano | H1: Modalidade | I1: Inicio vigencia | J1: Fim vigencia | K1: Situacao | L1: Meses | M1: Valor global (R$) | N1: Valor mensal (R$) | O1: R$/hab/ano | P1: Categoria do objeto | Q1: Objeto contratado | R1: Link PNCP
A2: MUNICIPIO DE POUSO REDONDO | B2: Prefeitura | C2: Pouso Redondo | D2: SC | E2: 17836 | F2: 1 · Ate 20 mil | G2: 2026 | H2: Dispensa | I2: 46157 | J2: 46522 | K2: =IF(J2>=TODAY(),"Vigente","Encerrado") -> Vigente | L2: =ROUND((J2-I2)/30.44,1) -> 12 | M2: 48000 | N2: =IF(L2=0,"",M2/L2) -> 4000 | O2: =IF(E2=0,"",N2*12/E2) -> 2.6911864 | P2: Licenciamento de obras e alvaras | Q2: Contratação de solução de software para implantação de processo digital no setor de Planejamento e Meio Ambiente, contemplando funcionalidades para análise de projetos, tramitação eletrônica de processos, gerenciamento e | R2: https://pncp.gov.br/app/contratos/contratos/83102681000126/2026/518
A3: MUNICIPIO DE CAFELANDIA | B3: Prefeitura | C3: Cafelândia | D3: PR | E3: 19844 | F3: 1 · Ate 20 mil | G3: 2025 | H3: Dispensa | I3: 45933 | J3: 46297 | K3: =IF(J3>=TODAY(),"Vigente","Encerrado") -> Vigente | L3: =ROUND((J3-I3)/30.44,1) -> 12 | M3: 48000 | N3: =IF(L3=0,"",M3/L3) -> 4000 | O3: =IF(E3=0,"",N3*12/E3) -> 2.4188672 | P3: Licenciamento de obras e alvaras | Q3: A PRESENTE CONTRATACAO TEM POR OBJETO A CONTRATACAO DE EMPRESA ESPECIALIZADA PARA A PRESTACAO DE SERVICOS E FORNECIMENTO DE LICENCA DE USO TEMPORARIA DE SISTEMA INFORMATIZADO INTEGRADO PARA GESTAO ELETRONICA DE PROCESSOS | R3: https://pncp.gov.br/app/contratos/contratos/78121878000172/2025/95
A4: MUNICIPIO DE BRASILANDIA | B4: Prefeitura | C4: Brasilândia | D4: MS | E4: 11840 | F4: 1 · Ate 20 mil | G4: 2025 | H4: Inexigibilidade | I4: 45972 | J4: 46336 | K4: =IF(J4>=TODAY(),"Vigente","Encerrado") -> Vigente | L4: =ROUND((J4-I4)/30.44,1) -> 12 | M4: 61800 | N4: =IF(L4=0,"",M4/L4) -> 5150 | O4: =IF(E4=0,"",N4*12/E4) -> 5.2195946 | P4: Licenciamento de obras e alvaras | Q4: Contratação de empresa especializada em Tecnologia da Informação e Comunicação (TIC), para fornecimento de licença de direito de uso temporário de “SISTEMA INTEGRADO DE LICENCIAMENTO DE OBRAS E GESTÃO DE PROCESSOS DIGITA | R4: https://pncp.gov.br/app/contratos/contratos/03184058000120/2025/81
A5: MUNICIPIO DE GUAPIACU | B5: Prefeitura | C5: Guapiaçu | D5: SP | E5: 22316 | F5: 2 · 20 a 100 mil | G5: 2026 | H5: Pregão - Eletrônico | I5: 46196 | J5: 46561 | K5: =IF(J5>=TODAY(),"Vigente","Encerrado") -> Vigente | L5: =ROUND((J5-I5)/30.44,1) -> 12 | M5: 63500 | N5: =IF(L5=0,"",M5/L5) -> 5291.6667 | O5: =IF(E5=0,"",N5*12/E5) -> 2.845492 | P5: Licenciamento de obras e alvaras | Q5: Contratação de solução tecnológica completa, fornecida em modelo Software como Serviço (SaaS), para gestão digital de processos de licenciamento urbano, fiscalização, regularização, análise técnica, gestão documental e a | R5: https://pncp.gov.br/app/contratos/contratos/45728326000178/2026/51
A6: MUNICIPIO DE JABOTICABAL | B6: Prefeitura | C6: Jaboticabal | D6: SP | E6: 73467 | F6: 2 · 20 a 100 mil | G6: 2025 | H6: Pregão - Eletrônico | I6: 45825 | J6: 46189 | K6: =IF(J6>=TODAY(),"Vigente","Encerrado") -> Encerrado | L6: =ROUND((J6-I6)/30.44,1) -> 12 | M6: 102000 | N6: =IF(L6=0,"",M6/L6) -> 8500 | O6: =IF(E6=0,"",N6*12/E6) -> 1.3883785 | P6: Licenciamento de obras e alvaras | Q6: Aquisição de licença de uso de Software (Licenciamento de Obras), 100% acessível via web, para protocolo, análise, fiscalização, gerenciamento, aprovação e emissão de Alvará de Obras, Certificado de Regularização, Certid | R6: https://pncp.gov.br/app/contratos/contratos/50387844000105/2025/1544
A7: MUNICIPIO DE PRUDENTOPOLIS | B7: Prefeitura | C7: Prudentópolis | D7: PR | E7: 50428 | F7: 2 · 20 a 100 mil | G7: 2025 | H7: Pregão - Eletrônico | I7: 45826 | J7: 46191 | K7: =IF(J7>=TODAY(),"Vigente","Encerrado") -> Encerrado | L7: =ROUND((J7-I7)/30.44,1) -> 12 | M7: 139960 | N7: =IF(L7=0,"",M7/L7) -> 11663.333 | O7: =IF(E7=0,"",N7*12/E7) -> 2.7754422 | P7: Licenciamento de obras e alvaras | Q7: Aquisicao do uso de licenca e implementacao de um sistema de protocolos digitais, que visa a automacao e digitalizacao dos processos administrativos, com enfase no licenciamento de obras e emissao de alvaras, licencas e | R7: https://pncp.gov.br/app/contratos/contratos/77003424000134/2025/247
A8: MUNICIPIO DE JOACABA | B8: Prefeitura | C8: Joaçaba | D8: SC | E8: 31509 | F8: 2 · 20 a 100 mil | G8: 2025 | H8: Pregão - Eletrônico | I8: 45993 | J8: 46358 | K8: =IF(J8>=TODAY(),"Vigente","Encerrado") -> Vigente | L8: =ROUND((J8-I8)/30.44,1) -> 12 | M8: 152600 | N8: =IF(L8=0,"",M8/L8) -> 12716.667 | O8: =IF(E8=0,"",N8*12/E8) -> 4.8430607 | P8: Licenciamento de obras e alvaras | Q8: Contratação de serviços técnicos especializados para fornecimento de licença de uso temporário de sistema informatizado integrado para gestão eletrônica de processos em nuvem (cloud), com funcionalidades de protocolo, an | R8: https://pncp.gov.br/app/contratos/contratos/82939380000199/2025/666
A9: MUNICIPIO DE GASPAR | B9: Prefeitura | C9: Gaspar | D9: SC | E9: 76982 | F9: 2 · 20 a 100 mil | G9: 2026 | H9: Pregão - Eletrônico | I9: 46191 | J9: 46555 | K9: =IF(J9>=TODAY(),"Vigente","Encerrado") -> Vigente | L9: =ROUND((J9-I9)/30.44,1) -> 12 | M9: 228000 | N9: =IF(L9=0,"",M9/L9) -> 19000 | O9: =IF(E9=0,"",N9*12/E9) -> 2.9617313 | P9: Licenciamento de obras e alvaras | Q9: CONTRATAÇÃO DE LICENÇA DE USO DE SISTEMA INTEGRADO CLOUD PARA GESTÃO ELETRÔNICA DE PROCESSOS (PROTOCOLO, ANÁLISE, APROVAÇÃO E EMISSÃO) E FLUXOS DE LICENCIAMENTO (OBRAS, ADM., AMBIENTAL E DEFESA CIVIL). | R9: https://pncp.gov.br/app/contratos/contratos/83102244000102/2026/473
A10: MUNICIPIO DE ITU | B10: Prefeitura | C10: Itu | D10: SP | E10: 174561 | F10: 3 · 100 a 500 mil | G10: 2025 | H10: Pregão - Eletrônico | I10: 45841 | J10: 46206 | K10: =IF(J10>=TODAY(),"Vigente","Encerrado") -> Encerrado | L10: =ROUND((J10-I10)/30.44,1) -> 12 | M10: 60500 | N10: =IF(L10=0,"",M10/L10) -> 5041.6667 | O10: =IF(E10=0,"",N10*12/E10) -> 0.34658372 | P10: Licenciamento de obras e alvaras | Q10: CONTRATAÇÃO DE EMPRESA ESPECIALIZADA NA PRESTAÇÃO DE SERVIÇOS DE LICENÇA DE USO TEMPORÁRIA, PELO PERÍODO DE 12 (DOZE) MESES, PARA SISTEMA INFORMATIZADO INTEGRADO PARA GESTÃO ELETRÔNICA DE PROCESSOS EM NUVEM (CLOUD), COM | R10: https://pncp.gov.br/app/contratos/contratos/46634440000100/2025/620
A11: MUNICIPIO DE CAMBE | B11: Prefeitura | C11: Cambé | D11: PR | E11: 111009 | F11: 3 · 100 a 500 mil | G11: 2024 | H11: Pregão - Eletrônico | I11: 45471 | J11: 45897 | K11: =IF(J11>=TODAY(),"Vigente","Encerrado") -> Encerrado | L11: =ROUND((J11-I11)/30.44,1) -> 14 | M11: 137667 | N11: =IF(L11=0,"",M11/L11) -> 9833.3571 | O11: =IF(E11=0,"",N11*12/E11) -> 1.0629794 | P11: Licenciamento de obras e alvaras | Q11: Fornecimento de sistema com soluções digitais para licenciamento completo de obras e fiscalização urbana, que contemple protocolo, análise, aprovação, fiscalização e emissão de diversos documentos através da Internet, pa | R11: https://pncp.gov.br/app/contratos/contratos/75732057000184/2024/254
A12: MUNICIPIO DE SANTA CRUZ DO SUL | B12: Prefeitura | C12: Santa Cruz do Sul | D12: RS | E12: 138104 | F12: 3 · 100 a 500 mil | G12: 2026 | H12: Pregão - Eletrônico | I12: 46099 | J12: 46463 | K12: =IF(J12>=TODAY(),"Vigente","Encerrado") -> Vigente | L12: =ROUND((J12-I12)/30.44,1) -> 12 | M12: 205000 | N12: =IF(L12=0,"",M12/L12) -> 17083.333 | O12: =IF(E12=0,"",N12*12/E12) -> 1.4843886 | P12: Licenciamento de obras e alvaras | Q12: Contratação de empresa especializada em fornecimento de sistema de tramitação digital de licenciamento de obras da Secretaria de Planejamento e Mobilidade Urbana - SEPLAN | R12: https://pncp.gov.br/app/contratos/contratos/95440517000108/2026/9
A13: MUNICIPIO DE PATOS DE MINAS | B13: Prefeitura | C13: Patos de Minas | D13: MG | E13: 167870 | F13: 3 · 100 a 500 mil | G13: 2025 | H13: Pregão - Eletrônico | I13: 45922 | J13: 47749 | K13: =IF(J13>=TODAY(),"Vigente","Encerrado") -> Vigente | L13: =ROUND((J13-I13)/30.44,1) -> 60 | M13: 1380000 | N13: =IF(L13=0,"",M13/L13) -> 23000 | O13: =IF(E13=0,"",N13*12/E13) -> 1.6441294 | P13: Licenciamento de obras e alvaras | Q13: [LICITANET] - [LICITANET] - CONTRATAÇÃO DE SISTEMA INFORMATIVO DESTINADO A PROVER À POPULAÇÃO FERRAMENTAS MODERNAS PARA A TRAMITAÇÃO DE ANUÊNCIAS, PERMISSÕES, SOLICITAÇÕES E PROCESSOS ADMINISTRATIVOS PERANTE A ADMINISTRA | R13: https://pncp.gov.br/app/contratos/contratos/18602011000107/2025/168
... A15: CONSORCIO INTERMUNICIPAL DO MEDIO VALE DO ITAJAI | B15: Consórcio | C15: Timbó | D15: SC | E15: 48903 | F15: 2 · 20 a 100 mil | G15: 2026 | H15: Pregão - Eletrônico | I15: 46055 | J15: 46414 | K15: =IF(J15>=TODAY(),"Vigente","Encerrado") -> Vigente | L15: =ROUND((J15-I15)/30.44,1) -> 11.8 | M15: 476199.54 | N15: =IF(L15=0,"",M15/L15) -> 40355.893 | O15: =IF(E15=0,"",N15*12/E15) -> 9.9026792 | P15: Licenciamento de obras e alvaras | Q15: Contratação de empresa especializada para fornecimento de licença de uso (locação) de sistema informatizado de gestão de processos do Serviço de Inspeção Municipal Consorciado, bem como da Gestão de Cultura e Turismo, in | R15: https://pncp.gov.br/app/contratos/contratos/03111139000109/2026/3

Sheet Contratos Gove
A1: Orgao contratante | B1: Tipo de entidade | C1: Municipio | D1: UF | E1: Populacao 2024 | F1: Faixa populacional | G1: Ano | H1: Modalidade | I1: Inicio vigencia | J1: Fim vigencia | K1: Situacao | L1: Meses | M1: Valor global (R$) | N1: Valor mensal (R$) | O1: R$/hab/ano | P1: Categoria do objeto | Q1: Objeto contratado | R1: Link PNCP
A2: MUNICIPIO DE SAO JOAO DO OESTE | B2: Prefeitura | C2: São João do Oeste | D2: SC | E2: 6446 | F2: 1 · Ate 20 mil | G2: 2025 | H2: Inexigibilidade | I2: 45870 | J2: 46234 | K2: =IF(J2>=TODAY(),"Vigente","Encerrado") -> Encerrado | L2: =ROUND((J2-I2)/30.44,1) -> 12 | M2: 24000 | N2: =IF(L2=0,"",M2/L2) -> 2000 | O2: =IF(E2=0,"",N2*12/E2) -> 3.7232392 | P2: Atendimento e relacionamento com o cidadao | Q2: Contratação direta, com fundamento no art. 74, inciso I, da Lei nº 14.133/2021, do fornecimento de licença de uso do software na modalidade SaaS (Software as a Service) denominado Plataforma Gove, ferramenta integrada de gestão do | R2: https://pncp.gov.br/app/contratos/contratos/80911936000103/2025/980
A3: MUNICIPIO DE IPE | B3: Prefeitura | C3: Ipê | D3: RS | E3: 5496 | F3: 1 · Ate 20 mil | G3: 2025 | H3: Inexigibilidade | I3: 45905 | J3: 46270 | K3: =IF(J3>=TODAY(),"Vigente","Encerrado") -> Vigente | L3: =ROUND((J3-I3)/30.44,1) -> 12 | M3: 59899.92 | N3: =IF(L3=0,"",M3/L3) -> 4991.66 | O3: =IF(E3=0,"",N3*12/E3) -> 10.898821 | P3: Atendimento e relacionamento com o cidadao | Q3: Contratacao de software SaaS de gerenciamento e de modernizacao do relacionamento do setor publico com cidadaos e empresas contemplando funcionalidades de gestao de contatos de relacionamento ativo e receptivo autonomo via multi | R3: https://pncp.gov.br/app/contratos/contratos/90544511000167/2025/2236
A4: MUNICIPIO DE COQUEIRAL | B4: Prefeitura | C4: Coqueiral | D4: MG | E4: 9197 | F4: 1 · Ate 20 mil | G4: 2025 | H4: Inexigibilidade | I4: 45915 | J4: 46280 | K4: =IF(J4>=TODAY(),"Vigente","Encerrado") -> Vigente | L4: =ROUND((J4-I4)/30.44,1) -> 12 | M4: 61899.96 | N4: =IF(L4=0,"",M4/L4) -> 5158.33 | O4: =IF(E4=0,"",N4*12/E4) -> 6.7304512 | P4: Dados e gestao tributaria | Q4: Contratação de empresa especializada no fornecimento de assinatura de software na modalidade SaaS de gerenciamento e de modernização do relacionamento do setor público com cidadãos e empresas, contemplando funcionalidades de gestã | R4: https://pncp.gov.br/app/contratos/contratos/18239624000121/2025/19
A5: MUNICIPIO DE BUENO BRANDAO | B5: Prefeitura | C5: Bueno Brandão | D5: MG | E5: 11161 | F5: 1 · Ate 20 mil | G5: 2025 | H5: Inexigibilidade | I5: 45916 | J5: 46281 | K5: =IF(J5>=TODAY(),"Vigente","Encerrado") -> Vigente | L5: =ROUND((J5-I5)/30.44,1) -> 12 | M5: 62400 | N5: =IF(L5=0,"",M5/L5) -> 5200 | O5: =IF(E5=0,"",N5*12/E5) -> 5.5908969 | P5: Dados e gestao tributaria | Q5: Contratação da empresa MUOVE BRASIL SA para prestação de serviços de locação do software denominado “GOVE” na modalidade SaaS de modernização do relacionamento do setor público com cidadãos e empresas, contemplando funcionalidades | R5: https://pncp.gov.br/app/contratos/contratos/18940098000122/2025/116
A6: MUNICIPIO DE BRACO DO TROMBUDO | B6: Prefeitura | C6: Braço do Trombudo | D6: SC | E6: 4203 | F6: 1 · Ate 20 mil | G6: 2026 | H6: Inexigibilidade | I6: 46247 | J6: 46612 | K6: =IF(J6>=TODAY(),"Vigente","Encerrado") -> Vigente | L6: =ROUND((J6-I6)/30.44,1) -> 12 | M6: 69820.56 | N6: =IF(L6=0,"",M6/L6) -> 5818.38 | O6: =IF(E6=0,"",N6*12/E6) -> 16.612077 | P6: Dados e gestao tributaria | Q6: Contratação de Solução Tecnológica de Gestão de Atendimento Digital, Comunicação Institucional Multicanal e Centralização Cadastral na Modalidade SaaS de licença de uso, na modalidade Software as a Service (SaaS). | R6: https://pncp.gov.br/app/contratos/contratos/95952230000167/2026/295
A7: MUNICIPIO DE TRAJANO DE MORAES | B7: Prefeitura | C7: Trajano de Moraes | D7: RJ | E7: 10652 | F7: 1 · Ate 20 mil | G7: 2025 | H7: Inexigibilidade | I7: 45938 | J7: 46303 | K7: =IF(J7>=TODAY(),"Vigente","Encerrado") -> Vigente | L7: =ROUND((J7-I7)/30.44,1) -> 12 | M7: 81798.6 | N7: =IF(L7=0,"",M7/L7) -> 6816.55 | O7: =IF(E7=0,"",N7*12/E7) -> 7.6791776 | P7: Outro / SaaS de gestao | Q7: CONTRATAÇÃO DE EMPRESA ESPECIALIZADA NO FORNECIMENTO DE SOFTWARE SAAS SOFTWARE AS A SERVICE | R7: https://pncp.gov.br/app/contratos/contratos/29115441000110/2025/188
A8: MUNICIPIO DE ITAPIRANGA | B8: Prefeitura | C8: Itapiranga | D8: SC | E8: 17149 | F8: 1 · Ate 20 mil | G8: 2025 | H8: Inexigibilidade | I8: 46002 | J8: 46366 | K8: =IF(J8>=TODAY(),"Vigente","Encerrado") -> Vigente | L8: =ROUND((J8-I8)/30.44,1) -> 12 | M8: 121508.52 | N8: =IF(L8=0,"",M8/L8) -> 10125.71 | O8: =IF(E8=0,"",N8*12/E8) -> 7.085458 | P8: Atendimento e relacionamento com o cidadao | Q8: FORNECIMENTO DE LICENÇA DE USO DO SOFTWARE NA MODALIDADE SAAS (SOFTWARE AS A SERVICE) DENOMINADO PLATAFORMA GOVE, FERRAMENTA INTEGRADA DE GESTÃO DO RELACIONAMENTO ENTRE O SETOR PÚBLICO E OS CIDADÃOS/EMPRESAS, COM FUNCIONALIDADES D | R8: https://pncp.gov.br/app/contratos/contratos/82821208000136/2025/2026
A9: MUNICIPIO DE MATINHOS | B9: Prefeitura | C9: Matinhos | D9: PR | E9: 41416 | F9: 2 · 20 a 100 mil | G9: 2025 | H9: Inexigibilidade | I9: 45854 | J9: 46219 | K9: =IF(J9>=TODAY(),"Vigente","Encerrado") -> Encerrado | L9: =ROUND((J9-I9)/30.44,1) -> 12 | M9: 111600 | N9: =IF(L9=0,"",M9/L9) -> 9300 | O9: =IF(E9=0,"",N9*12/E9) -> 2.6946108 | P9: Atendimento e relacionamento com o cidadao | Q9: CONTRATAÇÃO DE EMPRESA ESPECIALIZADA NA PRESTAÇÃO DE SERVIÇOS DE GESTÃO DA INFORMAÇÃO PARA OTIMIZAÇÃO DE DADOS CADASTRAIS MUNICIPAIS ATRAVÉS DE SOFTWARE E DISPONIBILIZAÇÃO DE SOFTWARE DE ATENDIMENTO AO CONTRIBUINTE VIA WHATSAPP | R9: https://pncp.gov.br/app/contratos/contratos/76017466000161/2025/56
A10: MUNICIPIO DE MORRO DO CHAPEU | B10: Prefeitura | C10: Morro do Chapéu | D10: BA | E10: 35224 | F10: 2 · 20 a 100 mil | G10: 2025 | H10: Pregão - Eletrônico | I10: 45726 | J10: 46090 | K10: =IF(J10>=TODAY(),"Vigente","Encerrado") -> Encerrado | L10: =ROUND((J10-I10)/30.44,1) -> 12 | M10: 119430 | N10: =IF(L10=0,"",M10/L10) -> 9952.5 | O10: =IF(E10=0,"",N10*12/E10) -> 3.390586 | P10: Atendimento e relacionamento com o cidadao | Q10: Contratação de empresa para prestação de serviços de locação de software na modalidade SAAS (solução tecnológica) para agilizar no atendimento aos contribuintes, através de plataforma de mensagens (whatzapp), para atender as neces | R10: https://pncp.gov.br/app/contratos/contratos/13717517000148/2025/58
A11: MUNICIPIO DE VERA CRUZ | B11: Prefeitura | C11: Vera Cruz | D11: BA | E11: 44978 | F11: 2 · 20 a 100 mil | G11: 2025 | H11: Inexigibilidade | I11: 45687 | J11: 46052 | K11: =IF(J11>=TODAY(),"Vigente","Encerrado") -> Encerrado | L11: =ROUND((J11-I11)/30.44,1) -> 12 | M11: 126400 | N11: =IF(L11=0,"",M11/L11) -> 10533.333 | O11: =IF(E11=0,"",N11*12/E11) -> 2.8102628 | P11: Atendimento e relacionamento com o cidadao | Q11: Contratação de software SaaS de gerenciamento e de modernização do relacionamento do setor público com cidadãos e empresas, contemplando funcionalidades de gestão de contatos, de relacionamento ativo e receptivo autônomo via múlti | R11: https://pncp.gov.br/app/contratos/contratos/13891130000103/2025/9
A12: MUNICIPIO DE GRAMADO | B12: Prefeitura | C12: Gramado | D12: RS | E12: 41621 | F12: 2 · 20 a 100 mil | G12: 2025 | H12: Pregão - Eletrônico | I12: 45946 | J12: 46311 | K12: =IF(J12>=TODAY(),"Vigente","Encerrado") -> Vigente | L12: =ROUND((J12-I12)/30.44,1) -> 12 | M12: 127200 | N12: =IF(L12=0,"",M12/L12) -> 10600 | O12: =IF(E12=0,"",N12*12/E12) -> 3.0561495 | P12: Atendimento e relacionamento com o cidadao | Q12: Contratação de ferramenta de comunicação multicanal, enriquecimento de dados e informações cadastrais de pessoas e empresas, com o objetivo de atender campanhas de comunicação da Secretaria da Fazenda. | R12: https://pncp.gov.br/app/contratos/contratos/88847082000155/2025/255
A13: MUNICIPIO DE ALEGRE | B13: Prefeitura | C13: Alegre | D13: ES | E13: 30744 | F13: 2 · 20 a 100 mil | G13: 2024 | H13: Inexigibilidade | I13: 45461 | J13: 45826 | K13: =IF(J13>=TODAY(),"Vigente","Encerrado") -> Encerrado | L13: =ROUND((J13-I13)/30.44,1) -> 12 | M13: 146385.96 | N13: =IF(L13=0,"",M13/L13) -> 12198.83 | O13: =IF(E13=0,"",N13*12/E13) -> 4.7614481 | P13: Dados e gestao tributaria | Q13: CONTRATACAO DE SOFTWARE COMO SERVICOS (SAAS - SOFTWARE A SERVICE), COM APOIO TECNICO ESPECIALIZADO EM ANALISE DE DADOS, CONTEMPLANDO INTEGRACAO, ANALISE DE INFORMACOES DE BASES CADASTRAIS E TRIBUTARIAS E NOTIFICACAO DE CONTRIBUINT | R13: https://pncp.gov.br/app/contratos/contratos/27174101000135/2024/35
... A32: FUNDO MUNICIPAL DA SAUDE DE SAO JOAO DO OESTE | B32: Fundo municipal | C32: São João do Oeste | D32: SC | E32: 6446 | F32: 1 · Ate 20 mil | G32: 2025 | H32: Inexigibilidade | I32: 45870 | J32: 46234 | K32: =IF(J32>=TODAY(),"Vigente","Encerrado") -> Encerrado | L32: =ROUND((J32-I32)/30.44,1) -> 12 | M32: 24000 | N32: =IF(L32=0,"",M32/L32) -> 2000 | O32: =IF(E32=0,"",N32*12/E32) -> 3.7232392 | P32: Atendimento e relacionamento com o cidadao | Q32: Contratação direta, com fundamento no art. 74, inciso I, da Lei nº 14.133/2021, do fornecimento de licença de uso do software na modalidade SaaS (Software as a Service) denominado Plataforma Gove, ferramenta integrada de gestão do | R32: https://pncp.gov.br/app/contratos/contratos/11418721000132/2025/192

Sheet Resumo por faixa
A1: Resumo por faixa · panorama dos concorrentes
A2: Valores mensais em R$ = valor global do contrato dividido pelos meses de vigencia. Base: abas de contratos.
A3: Vigentes conta apenas contratos ainda em vigor hoje. Minimo, maximo e mediana usam a base completa, para nao invalidar a amostra.
A5: 1 · 1DOC TECNOLOGIA · BENCHMARK DIRETO
A6: Objeto: protocolo, tramitacao de processos administrativos e gestao documental. Mesmo objeto do Protocolo 3.0.
A7: Faixa / entidade | B7: Contratos (n) | C7: Vigentes (n) | D7: Valor minimo | E7: Valor maximo | F7: Mediana (ticket) | G7: Mediana anual | H7: Confiabilidade
A8: PREFEITURAS
A9: Ate 20 mil habitantes | B9: =COUNT('Contratos 1Doc'!$N$2:$N$24) -> 23 | C9: =COUNTIF('Contratos 1Doc'!$K$2:$K$24,"Vigente") -> 9 | D9: =MIN('Contratos 1Doc'!$N$2:$N$24) -> 2070.15 | E9: =MAX('Contratos 1Doc'!$N$2:$N$24) -> 8575 | F9: =MEDIAN('Contratos 1Doc'!$N$2:$N$24) -> 3040 | G9: =F9*12 -> 36480 | H9: =IF(B9>=10,"Adequada",IF(B9>=5,"Limitada","Insuficiente")) -> Adequada
A10: 20 a 100 mil habitantes | B10: =COUNT('Contratos 1Doc'!$N$25:$N$60) -> 36 | C10: =COUNTIF('Contratos 1Doc'!$K$25:$K$60,"Vigente") -> 15 | D10: =MIN('Contratos 1Doc'!$N$25:$N$60) -> 675 | E10: =MAX('Contratos 1Doc'!$N$25:$N$60) -> 23478.261 | F10: =MEDIAN('Contratos 1Doc'!$N$25:$N$60) -> 8839.2 | G10: =F10*12 -> 106070.4 | H10: =IF(B10>=10,"Adequada",IF(B10>=5,"Limitada","Insuficiente")) -> Adequada
A11: 100 a 500 mil habitantes | B11: =COUNT('Contratos 1Doc'!$N$61:$N$70) -> 10 | C11: =COUNTIF('Contratos 1Doc'!$K$61:$K$70,"Vigente") -> 4 | D11: =MIN('Contratos 1Doc'!$N$61:$N$70) -> 1875 | E11: =MAX('Contratos 1Doc'!$N$61:$N$70) -> 67500 | F11: =MEDIAN('Contratos 1Doc'!$N$61:$N$70) -> 8960.2 | G11: =F11*12 -> 107522.4 | H11: =IF(B11>=10,"Adequada",IF(B11>=5,"Limitada","Insuficiente")) -> Adequada
A12: Acima de 500 mil habitantes | B12: =COUNT('Contratos 1Doc'!$N$71:$N$72) -> 2 | C12: =COUNTIF('Contratos 1Doc'!$K$71:$K$72,"Vigente") -> 1 | D12: =MIN('Contratos 1Doc'!$N$71:$N$72) -> 996.98817 | E12: =MAX('Contratos 1Doc'!$N$71:$N$72) -> 5800 | F12: =MEDIAN('Contratos 1Doc'!$N$71:$N$72) -> 3398.4941 | G12: =F12*12 -> 40781.929 | H12: =IF(B12>=10,"Adequada",IF(B12>=5,"Limitada","Insuficiente")) -> Insuficiente
A13: Total prefeituras | B13: =COUNT('Contratos 1Doc'!$N$2:$N$72) -> 71 | C13: =COUNTIF('Contratos 1Doc'!$K$2:$K$72,"Vigente") -> 29 | D13: =MIN('Contratos 1Doc'!$N$2:$N$72) -> 675 | E13: =MAX('Contratos 1Doc'!$N$2:$N$72) -> 67500 | F13: =MEDIAN('Contratos 1Doc'!$N$2:$N$72) -> 5400 | G13: =F13*12 -> 64800 | H13: =IF(B13>=10,"Adequada",IF(B13>=5,"Limitada","Insuficiente")) -> Adequada
A14: ENTIDADES VINCULADAS
A15: Camara Municipal | B15: =COUNT('Contratos 1Doc'!$N$73:$N$85) -> 13 | C15: =COUNTIF('Contratos 1Doc'!$K$73:$K$85,"Vigente") -> 8 | D15: =MIN('Contratos 1Doc'!$N$73:$N$85) -> 794.92 | E15: =MAX('Contratos 1Doc'!$N$73:$N$85) -> 8441.6667 | F15: =MEDIAN('Contratos 1Doc'!$N$73:$N$85) -> 2200 | G15: =F15*12 -> 26400 | H15: =IF(B15>=10,"Adequada",IF(B15>=5,"Limitada","Insuficiente")) -> Adequada
A16: Autarquia / Fundacao | B16: =COUNT('Contratos 1Doc'!$N$86:$N$95) -> 10 | C16: =COUNTIF('Contratos 1Doc'!$K$86:$K$95,"Vigente") -> 7 | D16: =MIN('Contratos 1Doc'!$N$86:$N$95) -> 1300 | E16: =MAX('Contratos 1Doc'!$N$86:$N$95) -> 13433.33 | F16: =MEDIAN('Contratos 1Doc'!$N$86:$N$95) -> 4136.2333 | G16: =F16*12 -> 49634.8 | H16: =IF(B16>=10,"Adequada",IF(B16>=5,"Limitada","Insuficiente")) -> Adequada
A17: Consorcio publico | B17: =COUNT('Contratos 1Doc'!$N$96:$N$112) -> 17 | C17: =COUNTIF('Contratos 1Doc'!$K$96:$K$112,"Vigente") -> 7 | D17: =MIN('Contratos 1Doc'!$N$96:$N$112) -> 270 | E17: =MAX('Contratos 1Doc'!$N$96:$N$112) -> 8100 | F17: =MEDIAN('Contratos 1Doc'!$N$96:$N$112) -> 2100 | G17: =F17*12 -> 25200 | H17: =IF(B17>=10,"Adequada",IF(B17>=5,"Limitada","Insuficiente")) -> Adequada
A18: Outros orgaos | B18: =COUNT('Contratos 1Doc'!$N$113:$N$115) -> 3 | C18: =COUNTIF('Contratos 1Doc'!$K$113:$K$115,"Vigente") -> 0 | D18: =MIN('Contratos 1Doc'!$N$113:$N$115) -> 2683.3333 | E18: =MAX('Contratos 1Doc'!$N$113:$N$115) -> 5800 | F18: =MEDIAN('Contratos 1Doc'!$N$113:$N$115) -> 3000 | G18: =F18*12 -> 36000 | H18: =IF(B18>=10,"Adequada",IF(B18>=5,"Limitada","Insuficiente")) -> Insuficiente
A19: TOTAL GERAL | B19: =COUNT('Contratos 1Doc'!$N$2:$N$115) -> 114 | C19: =COUNTIF('Contratos 1Doc'!$K$2:$K$115,"Vigente") -> 51 | D19: =MIN('Contratos 1Doc'!$N$2:$N$115) -> 270 | E19: =MAX('Contratos 1Doc'!$N$2:$N$115) -> 67500 | F19: =MEDIAN('Contratos 1Doc'!$N$2:$N$115) -> 4262.1733 | G19: =F19*12 -> 51146.08 | H19: =IF(B19>=10,"Adequada",IF(B19>=5,"Limitada","Insuficiente")) -> Adequada
A21: Parametros gerais
A22: Contratos de 12 meses | B22: =COUNTIF('Contratos 1Doc'!$L$2:$L$115,12) -> 96
A23: Contratos por Dispensa | B23: =COUNTIF('Contratos 1Doc'!$H$2:$H$115,"Dispensa") -> 62
A24: Contratos por Pregao Eletronico | B24: =COUNTIF('Contratos 1Doc'!$H$2:$H$115,"Pregão - Eletrônico") -> 41
A25: Contratos por Inexigibilidade | B25: =COUNTIF('Contratos 1Doc'!$H$2:$H$115,"Inexigibilidade") -> 9
A26: Outras modalidades | B26: =B19-B23-B24-B25 -> 2
A27: Mediana R$/habitante/ano | B27: =MEDIAN('Contratos 1Doc'!$O$2:$O$115) -> 1.8736285
A28: Piso observado (menor mensal, prefeituras) | B28: =MIN('Contratos 1Doc'!$N$2:$N$72) -> 675
A30: 2 · APROVA DIGITAL · REFERENCIA ADJACENTE
A31: Objeto predominante: licenciamento de obras, alvaras e aprovacao de projetos. Referencia de teto, nao preco comparavel.
A32: Faixa / entidade | B32: Contratos (n) | C32: Vigentes (n) | D32: Valor minimo | E32: Valor maximo | F32: Mediana (ticket) | G32: Mediana anual | H32: Confiabilidade
A33: PREFEITURAS
A34: Ate 20 mil habitantes | B34: =COUNT('Contratos Aprova'!$N$2:$N$4) -> 3 | C34: =COUNTIF('Contratos Aprova'!$K$2:$K$4,"Vigente") -> 3 | D34: =MIN('Contratos Aprova'!$N$2:$N$4) -> 4000 | E34: =MAX('Contratos Aprova'!$N$2:$N$4) -> 5150 | F34: =MEDIAN('Contratos Aprova'!$N$2:$N$4) -> 4000 | G34: =F34*12 -> 48000 | H34: =IF(B34>=10,"Adequada",IF(B34>=5,"Limitada","Insuficiente")) -> Insuficiente
A35: 20 a 100 mil habitantes | B35: =COUNT('Contratos Aprova'!$N$5:$N$9) -> 5 | C35: =COUNTIF('Contratos Aprova'!$K$5:$K$9,"Vigente") -> 3 | D35: =MIN('Contratos Aprova'!$N$5:$N$9) -> 5291.6667 | E35: =MAX('Contratos Aprova'!$N$5:$N$9) -> 19000 | F35: =MEDIAN('Contratos Aprova'!$N$5:$N$9) -> 11663.333 | G35: =F35*12 -> 139960 | H35: =IF(B35>=10,"Adequada",IF(B35>=5,"Limitada","Insuficiente")) -> Limitada
A36: 100 a 500 mil habitantes | B36: =COUNT('Contratos Aprova'!$N$10:$N$14) -> 5 | C36: =COUNTIF('Contratos Aprova'!$K$10:$K$14,"Vigente") -> 2 | D36: =MIN('Contratos Aprova'!$N$10:$N$14) -> 5041.6667 | E36: =MAX('Contratos Aprova'!$N$10:$N$14) -> 24833.333 | F36: =MEDIAN('Contratos Aprova'!$N$10:$N$14) -> 17083.333 | G36: =F36*12 -> 205000 | H36: =IF(B36>=10,"Adequada",IF(B36>=5,"Limitada","Insuficiente")) -> Limitada
A37: Total prefeituras | B37: =COUNT('Contratos Aprova'!$N$2:$N$14) -> 13 | C37: =COUNTIF('Contratos Aprova'!$K$2:$K$14,"Vigente") -> 8 | D37: =MIN('Contratos Aprova'!$N$2:$N$14) -> 4000 | E37: =MAX('Contratos Aprova'!$N$2:$N$14) -> 24833.333 | F37: =MEDIAN('Contratos Aprova'!$N$2:$N$14) -> 9833.3571 | G37: =F37*12 -> 118000.29 | H37: =IF(B37>=10,"Adequada",IF(B37>=5,"Limitada","Insuficiente")) -> Adequada
A38: ENTIDADES VINCULADAS
A39: Consorcio publico | B39: =COUNT('Contratos Aprova'!$N$15:$N$15) -> 1 | C39: =COUNTIF('Contratos Aprova'!$K$15:$K$15,"Vigente") -> 1 | D39: =MIN('Contratos Aprova'!$N$15:$N$15) -> 40355.893 | E39: =MAX('Contratos Aprova'!$N$15:$N$15) -> 40355.893 | F39: =MEDIAN('Contratos Aprova'!$N$15:$N$15) -> 40355.893 | G39: =F39*12 -> 484270.72 | H39: =IF(B39>=10,"Adequada",IF(B39>=5,"Limitada","Insuficiente")) -> Insuficiente
A40: TOTAL GERAL | B40: =COUNT('Contratos Aprova'!$N$2:$N$15) -> 14 | C40: =COUNTIF('Contratos Aprova'!$K$2:$K$15,"Vigente") -> 9 | D40: =MIN('Contratos Aprova'!$N$2:$N$15) -> 4000 | E40: =MAX('Contratos Aprova'!$N$2:$N$15) -> 40355.893 | F40: =MEDIAN('Contratos Aprova'!$N$2:$N$15) -> 10748.345 | G40: =F40*12 -> 128980.14 | H40: =IF(B40>=10,"Adequada",IF(B40>=5,"Limitada","Insuficiente")) -> Adequada
A42: Parametros gerais
A43: Contratos de 12 meses | B43: =COUNTIF('Contratos Aprova'!$L$2:$L$15,12) -> 11
A44: Contratos por Dispensa | B44: =COUNTIF('Contratos Aprova'!$H$2:$H$15,"Dispensa") -> 2
...

Sheet Proposta de preco
A1: Protocolo 3.0 · Modelo parametrico de precificacao
A2: Preencha apenas as celulas azuis. Tudo em preto e formula. Amarelo exige decisao antes de virar tabela oficial.
A3: O preco deriva de UMA base de referencia. Aprova e Gove aparecem como comparacao, nao como base de calculo - objetos diferentes.
A5: 1 · Parametros globais
A6: Base de referencia do benchmark | B6: 1Doc | C6: Valores aceitos: 1Doc, Aprova ou Gove. Recomendado 1Doc - unico com o mesmo objeto.
A7: Prazo padrao de contrato (meses) | B7: 12 | C7: Padrao de mercado: 96 dos 114 contratos da 1Doc sao de 12 meses.
A8: Implantacao como % da assinatura anual | B8: 0.25 | C8: Premissa. Substituir pelo custo real de implantacao da Centi.
A9: Desconto maximo por alcada comercial | B9: 0.1 | C9: Concedido apenas contra contrapartida contratual.
A10: Reajuste anual previsto em contrato | B10: 0.045 | C10: Indice a definir em contrato, conforme legislacao aplicavel.
A11: Limite de dispensa vigente (R$/ano) | C11: PREENCHER. Atualizado por decreto - validar com o juridico.
A13: 2 · Prefeituras · preco por faixa
A14: Fator: 1,00 = paridade com a base escolhida. Abaixo de 1 = entrada por preco. Acima de 1 = premio, exige diferenciacao comprovada.
A15: Faixa | B15: Mediana 1Doc | C15: Mediana Aprova | D15: Mediana Gove | E15: Base escolhida | F15: Fator de posicionamento | G15: Assinatura mensal | H15: Assinatura anual | I15: Implantacao (unico) | J15: Contrato ano 1 | K15: Cabe em dispensa?
A16: Ate 20 mil habitantes | B16: ='Resumo por faixa'!F9 -> 3040 | C16: ='Resumo por faixa'!F34 -> 4000 | D16: ='Resumo por faixa'!F56 -> 5200 | E16: =IF($B$6="Aprova",IF(ISNUMBER(C16),C16,B16),IF($B$6="Gove",IF(ISNUMBER(D16),D16,B16),B16)) -> 3040 | F16: 0.85 | G16: =ROUND(E16*F16,-1) -> 2580 | H16: =G16*12 -> 30960 | I16: =ROUND(H16*$B$8,-1) -> 7740 | J16: =G16*$B$7+I16 -> 38700 | K16: =IF($B$11="","preencher limite",IF(J16<=$B$11,"Sim","Nao")) -> preencher limite
A17: 20 a 100 mil habitantes | B17: ='Resumo por faixa'!F10 -> 8839.2 | C17: ='Resumo por faixa'!F35 -> 11663.333 | D17: ='Resumo por faixa'!F57 -> 14865.92 | E17: =IF($B$6="Aprova",IF(ISNUMBER(C17),C17,B17),IF($B$6="Gove",IF(ISNUMBER(D17),D17,B17),B17)) -> 8839.2 | F17: 0.9 | G17: =ROUND(E17*F17,-1) -> 7960 | H17: =G17*12 -> 95520 | I17: =ROUND(H17*$B$8,-1) -> 23880 | J17: =G17*$B$7+I17 -> 119400 | K17: =IF($B$11="","preencher limite",IF(J17<=$B$11,"Sim","Nao")) -> preencher limite
A18: 100 a 500 mil habitantes | B18: ='Resumo por faixa'!F11 -> 8960.2 | C18: ='Resumo por faixa'!F36 -> 17083.333 | D18: ='Resumo por faixa'!F58 -> 22571.5 | E18: =IF($B$6="Aprova",IF(ISNUMBER(C18),C18,B18),IF($B$6="Gove",IF(ISNUMBER(D18),D18,B18),B18)) -> 8960.2 | F18: 0.95 | G18: =ROUND(E18*F18,-1) -> 8510 | H18: =G18*12 -> 102120 | I18: =ROUND(H18*$B$8,-1) -> 25530 | J18: =G18*$B$7+I18 -> 127650 | K18: =IF($B$11="","preencher limite",IF(J18<=$B$11,"Sim","Nao")) -> preencher limite
A19: Acima de 500 mil habitantes | B19: ='Resumo por faixa'!F12 -> 3398.4941 | C19: sem amostra | D19: sem amostra | E19: =IF($B$6="Aprova",IF(ISNUMBER(C19),C19,B19),IF($B$6="Gove",IF(ISNUMBER(D19),D19,B19),B19)) -> 3398.4941 | F19: 1 | G19: =ROUND(E19*F19,-1) -> 3400 | H19: =G19*12 -> 40800 | I19: =ROUND(H19*$B$8,-1) -> 10200 | J19: =G19*$B$7+I19 -> 51000 | K19: =IF($B$11="","preencher limite",IF(J19<=$B$11,"Sim","Nao")) -> preencher limite
A20: "sem amostra" indica que o concorrente nao tem contratos naquela faixa. A base escolhida cai automaticamente para a 1Doc.
A22: 2b · Posicionamento resultante em relacao a cada concorrente
A23: Quanto o preco proposto representa da mediana de cada fornecedor. 100% = paridade.
A24: Faixa | B24: Assinatura mensal | C24: vs 1Doc (protocolo) | D24: vs Aprova (licenciamento) | E24: vs Gove (dados)
A25: Ate 20 mil habitantes | B25: =G16 -> 2580 | C25: =IFERROR(G16/B16,"-") -> 0.84868421 | D25: =IF(ISNUMBER(C16),G16/C16,"sem amostra") -> 0.645 | E25: =IF(ISNUMBER(D16),G16/D16,"sem amostra") -> 0.49615385
A26: 20 a 100 mil habitantes | B26: =G17 -> 7960 | C26: =IFERROR(G17/B17,"-") -> 0.90053398 | D26: =IF(ISNUMBER(C17),G17/C17,"sem amostra") -> 0.68248071 | E26: =IF(ISNUMBER(D17),G17/D17,"sem amostra") -> 0.5354529
A27: 100 a 500 mil habitantes | B27: =G18 -> 8510 | C27: =IFERROR(G18/B18,"-") -> 0.94975559 | D27: =IF(ISNUMBER(C18),G18/C18,"sem amostra") -> 0.49814634 | E27: =IF(ISNUMBER(D18),G18/D18,"sem amostra") -> 0.37702412
A28: Acima de 500 mil habitantes | B28: =G19 -> 3400 | C28: =IFERROR(G19/B19,"-") -> 1.0004431 | D28: =IF(ISNUMBER(C19),G19/C19,"sem amostra") -> sem amostra | E28: =IF(ISNUMBER(D19),G19/D19,"sem amostra") -> sem amostra
A30: 3 · Entidades vinculadas · base propria, nao usar faixa populacional
A31: Somente a 1Doc tem amostra relevante para Camara, autarquia e consorcio. Aprova e Gove nao entram aqui.
A32: Tipo de entidade | B32: Mediana 1Doc | C32: Amostra (n) | D32: Fator de posicionamento | E32: Assinatura mensal | F32: Assinatura anual | G32: Implantacao (unico) | H32: Contrato ano 1 | I32: Observacao
A33: Camara Municipal | B33: ='Resumo por faixa'!F15 -> 2200 | C33: ='Resumo por faixa'!B15 -> 13 | D33: 0.9 | E33: =ROUND(B33*D33,-1) -> 1980 | F33: =E33*12 -> 23760 | G33: =ROUND(F33*$B$8,-1) -> 5940 | H33: =E33*$B$7+G33 -> 29700 | I33: Apenas tramitacao administrativa. Nao vender como sistema legislativo.
A34: Autarquia / Fundacao | B34: ='Resumo por faixa'!F16 -> 4136.2333 | C34: ='Resumo por faixa'!B16 -> 10 | D34: 0.9 | E34: =ROUND(B34*D34,-1) -> 3720 | F34: =E34*12 -> 44640 | G34: =ROUND(F34*$B$8,-1) -> 11160 | H34: =E34*$B$7+G34 -> 55800 | I34: Volume alto no saneamento. Precificar por usuarios.
A35: Consorcio publico | B35: ='Resumo por faixa'!F17 -> 2100 | C35: ='Resumo por faixa'!B17 -> 17 | D35: 0.9 | E35: =ROUND(B35*D35,-1) -> 1890 | F35: =E35*12 -> 22680 | G35: =ROUND(F35*$B$8,-1) -> 5670 | H35: =E35*$B$7+G35 -> 28350 | I35: Ticket baixo. O valor esta no acesso aos municipios consorciados.
A37: 4A · Teste de piso · o preco com desconto maximo resiste ao menor contrato de cada concorrente?
A38: Piso = menor valor mensal observado naquela faixa, por fornecedor. Contratos parciais puxam o piso para baixo - tratar como alerta, nao como veredito.
A39: Faixa | B39: Assinatura mensal | C39: Com desconto maximo | D39: Piso 1Doc na faixa | E39: Piso Aprova na faixa | F39: Piso Gove na faixa | G39: Situacao
A40: Ate 20 mil habitantes | B40: =G16 -> 2580 | C40: =G16*(1-$B$9) -> 2322 | D40: ='Resumo por faixa'!D9 -> 2070.15 | E40: ='Resumo por faixa'!D34 -> 4000 | F40: ='Resumo por faixa'!D56 -> 2000 | G40: =IF(C40<D40,"ABAIXO do piso 1Doc",IF(AND(ISNUMBER(E40),C40<E40),"Abaixo do piso Aprova",IF(AND(ISNUMBER(F40),C40<F40),"Abaixo do piso Gove","Acima de todos os pisos"))) -> Abaixo do piso Aprova
A41: 20 a 100 mil habitantes | B41: =G17 -> 7960 | C41: =G17*(1-$B$9) -> 7164 | D41: ='Resumo por faixa'!D10 -> 675 | E41: ='Resumo por faixa'!D35 -> 5291.6667 | F41: ='Resumo por faixa'!D57 -> 9300 | G41: =IF(C41<D41,"ABAIXO do piso 1Doc",IF(AND(ISNUMBER(E41),C41<E41),"Abaixo do piso Aprova",IF(AND(ISNUMBER(F41),C41<F41),"Abaixo do piso Gove","Acima de todos os pisos"))) -> Abaixo do piso Gove
A42: 100 a 500 mil habitantes | B42: =G18 -> 8510 | C42: =G18*(1-$B$9) -> 7659 | D42: ='Resumo por faixa'!D11 -> 1875 | E42: ='Resumo por faixa'!D36 -> 5041.6667 | F42: ='Resumo por faixa'!D58 -> 13989.108 | G42: =IF(C42<D42,"ABAIXO do piso 1Doc",IF(AND(ISNUMBER(E42),C42<E42),"Abaixo do piso Aprova",IF(AND(ISNUMBER(F42),C42<F42),"Abaixo do piso Gove","Acima de todos os pisos"))) -> Abaixo do piso Gove
A43: Acima de 500 mil habitantes | B43: =G19 -> 3400 | C43: =G19*(1-$B$9) -> 3060 | D43: ='Resumo por faixa'!D12 -> 996.98817 | E43: sem amostra | F43: sem amostra | G43: =IF(C43<D43,"ABAIXO do piso 1Doc",IF(AND(ISNUMBER(E43),C43<E43),"Abaixo do piso Aprova",IF(AND(ISNUMBER(F43),C43<F43),"Abaixo do piso Gove","Acima de todos os pisos"))) -> Acima de todos os pisos
A45: 4B · Teste de orcamento · quanto o preco representa do que o municipio ja paga a cada fornecedor
A46: Nao e concorrencia direta com Aprova e Gove. E medida do espaco disponivel no orcamento municipal de SaaS de gestao.
...
